<?xml version='1.0'?>

<robot name="bot" xmlns:xacro="http://www.ros.org/wiki/xacro">

  <!-- RViz colors -->
  <xacro:include filename="$(find snowbot123)/urdf/materials.xacro" />

  <!-- STEP 1 - Robot footprint -->
  <link name="base_footprint"></link>

  <!-- STEP 2 - Robot chassis = base_link -->
  <joint name="base_footprint_joint" type="fixed">
    <origin xyz="0 0 0" rpy="0 0 0" />
    <parent link="base_footprint"/>
    <child link="base_link" />
  </joint>

   <link name="base_link">
    <visual>
      <origin xyz="0 0 0.11" rpy="0 0 0"/>
      <geometry>
        <box size="0.40 0.30 0.02"/>
      </geometry>
      <material name="orange">
        <color rgba="1.0 0.65 0.0 1.0"/>
      </material>
    </visual>

    <collision>
      <origin xyz="0 0 0.18"/>
      <geometry>
        <box size="0.40 0.30 0.02"/>
      </geometry>
    </collision>

    <inertial>
      <origin xyz="0 0 0.18"/>
      <mass value="10.0"/>
      <inertia ixx="0.061" iyy="0.075" izz="0.136" ixy="0" ixz="0" iyz="0"/>
    </inertial>
  </link>


  <!-- STEP 3 - Wheels -->
  <joint type="continuous" name="front_left_wheel_joint">
    <origin xyz="0.15 0.15 0" rpy="-1.5707 0 0"/>
    <child link="front_left_wheel"/>
    <parent link="base_link"/>
    <axis xyz="0 0 1" rpy="0 0 0"/>
    <limit effort="10000" velocity="10"/>
    <dynamics damping="1.0" friction="1.0"/>
  </joint>

  <link name='front_left_wheel'>
    <inertial>
      <mass value="2.0"/>
      <origin xyz="0 0 0" rpy="0 0 0"/>
      <inertia
          ixx="0.145833" ixy="0" ixz="0"
          iyy="0.145833" iyz="0"
          izz="0.125"
      />
    </inertial>

    <collision>
      <geometry>
        <sphere radius=".1"/>
      </geometry>
    </collision>

    <visual name='front_left_wheel_visual'>
      <origin xyz="0 0 0" rpy="1.5707 0 0"/>
      <geometry>
        <!-- <sphere radius=".1"/> -->
        <mesh filename="package://snowbot123/meshes/mecanum_wheel_left.STL" scale="0.002 .002 0.002"/>
      </geometry>
      <material name="green"/>
    </visual>
  </link>

  <joint type="continuous" name="rear_left_wheel_joint">
    <origin xyz="-0.15 0.15 0" rpy="-1.5707 0 0"/>
    <child link="rear_left_wheel"/>
    <parent link="base_link"/>
    <axis xyz="0 0 1" rpy="0 0 0"/>
    <limit effort="10000" velocity="10"/>
    <dynamics damping="1.0" friction="1.0"/>
  </joint>

  <link name='rear_left_wheel'>
    <inertial>
      <mass value="2.0"/>
      <origin xyz="0 0 0" rpy="0 0 0"/>
      <inertia
          ixx="0.145833" ixy="0" ixz="0"
          iyy="0.145833" iyz="0"
          izz="0.125"
      />
    </inertial>

    <collision>
      <geometry>
        <sphere radius=".1"/>
      </geometry>
    </collision>

    <visual name='rear_left_wheel_visual'>
      <origin xyz="0 0 0" rpy="1.5707 0 0"/>
      <geometry>
        <!-- <sphere radius=".1"/> -->
        <mesh filename="package://snowbot123/meshes/mecanum_wheel_right.STL" scale="0.002 .002 0.002"/>
      </geometry>
      <material name="green"/>
    </visual>
  </link>

  <joint type="continuous" name="front_right_wheel_joint">
    <origin xyz="0.15 -0.15 0" rpy="-1.5707 0 0"/>
    <child link="front_right_wheel"/>
    <parent link="base_link"/>
    <axis xyz="0 0 1" rpy="0 0 0"/>
    <limit effort="10000" velocity="10"/>
    <dynamics damping="1.0" friction="1.0"/>
  </joint>

  <link name='front_right_wheel'>
    <inertial>
      <mass value="2.0"/>
      <origin xyz="0 0 0" rpy="0 0 0"/>
      <inertia
          ixx="0.145833" ixy="0" ixz="0"
          iyy="0.145833" iyz="0"
          izz="0.125"
      />
    </inertial>

    <collision>
      <geometry>
        <sphere radius=".1"/>
      </geometry>
    </collision>

    <visual name='front_right_wheel_visual'>
      <origin xyz="0 0 0" rpy="1.5707 0 0"/>
      <geometry>
        <!-- <sphere radius=".1"/> -->
        <mesh filename="package://snowbot123/meshes/mecanum_wheel_right.STL" scale="0.002 .002 0.002"/>
      </geometry>
      <material name="green"/>
    </visual>
  </link>

  <joint type="continuous" name="rear_right_wheel_joint">
    <origin xyz="-0.15 -0.15 0" rpy="-1.5707 0 0"/>
    <child link="rear_right_wheel"/>
    <parent link="base_link"/>
    <axis xyz="0 0 1" rpy="0 0 0"/>
    <limit effort="10000" velocity="10"/>
    <dynamics damping="1.0" friction="1.0"/>
  </joint>

  <link name='rear_right_wheel'>
    <inertial>
      <mass value="2.0"/>
      <origin xyz="0 0 0" rpy="0 0 0"/>
      <inertia
          ixx="0.145833" ixy="0" ixz="0"
          iyy="0.145833" iyz="0"
          izz="0.125"
      />
    </inertial>

    <collision>
      <geometry>
        <sphere radius=".1"/>
      </geometry>
    </collision>

    <visual name='rear_right_wheel_visual'>
      <origin xyz="0 0 0" rpy="1.5707 0 0"/>
      <geometry>
        <!-- <sphere radius=".1"/> -->
        <mesh filename="package://snowbot123/meshes/mecanum_wheel_left.STL" scale="0.002 .002 0.002"/>
      </geometry>
      <material name="green"/>
    </visual>
  </link>
<!-- ==================== LIDAR ==================== -->
  <link name="lidar_link">
    <visual>
      <geometry>
        <cylinder radius="0.045" length="0.0755"/>
      </geometry>
    </visual>
  </link>

  <joint name="lidar_joint" type="fixed">
    <parent link="base_link"/>
    <child link="lidar_link"/>
    <origin xyz="0.095 0 0.15075"/>
  </joint>

  <!-- ==================== CAMERA ==================== -->
  <link name="camera_link">
    <visual>
      <geometry>
        <box size="0.06 0.05 0.0315"/>
      </geometry>
    </visual>
  </link>

  <joint name="camera_joint" type="fixed">
    <parent link="lidar_link"/>
    <child link="camera_link"/>
    <origin xyz="0 0 0.0535"/>
  </joint>

  <!-- ==================== IMU ==================== -->
  <link name="imu_link"/>

  <joint name="imu_joint" type="fixed">
    <parent link="base_link"/>
    <child link="imu_link"/>
    <origin xyz="0 0 0.20"/>
  </joint>


</robot>